<sdf version='1.11'>
  <model name='quadcopter'>
    <link name='base_link'>
      <inertial>
        <pose>0 0 0 0 0 0</pose>
        <mass>1.5</mass>
        <inertia>
          <ixx>0.10000000000000001</ixx>
          <ixy>0</ixy>
          <ixz>0</ixz>
          <iyy>0.10000000000000001</iyy>
          <iyz>0</iyz>
          <izz>0.10000000000000001</izz>
        </inertia>
      </inertial>
      <collision name='base_link_collision'>
        <pose>0 0 0.05 -1.585 0 0</pose>
        <geometry>
          <mesh>
            <scale>1 1 1</scale>
            <uri>file:///home/aerobase/drone_model/src/drone_description_backup/meshes/base_link.STL</uri>
          </mesh>
        </geometry>
      </collision>

      <collision name='base_link_fixed_joint_lump__front_left_collision_1'>
        <pose>0.20000000000000001 0.20000000000000001 0.050000000000000003 0 0 0</pose>
        <geometry>
          <mesh>
            <scale>0.5 0.5 0.5</scale>
            <uri>file:///home/aerobase/drone_model/src/drone_description_backup/meshes/rotor1.STL</uri>
          </mesh>
        </geometry>
      </collision>
      <collision name='base_link_fixed_joint_lump__front_right_collision_2'>
        <pose>0.20000000000000001 -0.20000000000000001 0.050000000000000003 0 0 0</pose>
        <geometry>
          <mesh>
            <scale>0.5 0.5 0.5</scale>
            <uri>file:///home/aerobase/drone_model/src/drone_description_backup/meshes/rotor2.STL</uri>
          </mesh>
        </geometry>
      </collision>
      <collision name='base_link_fixed_joint_lump__rear_left_collision_3'>
        <pose>-0.20000000000000001 0.20000000000000001 0.050000000000000003 0 0 0</pose>
        <geometry>
          <mesh>
            <scale>0.5 0.5 0.5</scale>
            <uri>file:///home/aerobase/drone_model/src/drone_description_backup/meshes/rotor3.STL</uri>
          </mesh>
        </geometry>
      </collision>
      <collision name='base_link_fixed_joint_lump__rear_right_collision_4'>
        <pose>-0.20000000000000001 -0.20000000000000001 0.050000000000000003 0 0 0</pose>
        <geometry>
          <mesh>
            <scale>0.5 0.5 0.5</scale>
            <uri>file:///home/aerobase/drone_model/src/drone_description_backup/meshes/rotor4.STL</uri>
          </mesh>
        </geometry>
      </collision>
      <visual name='base_link_visual'>
        <pose>0 0 0.05 -1.585 0 0</pose>
        <geometry>
          <mesh>
            <scale>1 1 1</scale>
            <uri>file:///home/aerobase/drone_model/src/drone_description_backup/meshes/base_link.STL</uri>
          </mesh>
        </geometry>
        <material>
          <diffuse>0.875 0.875 0.875 1</diffuse>
          <ambient>0.875 0.875 0.875 1</ambient>
        </material>
      </visual>
      <visual name='base_link_fixed_joint_lump__front_left_visual_1'>
        <pose>0.2 0.2 0 0 0 0</pose>
        <geometry>
          <mesh>
            <scale>0.5 0.5 0.5</scale>
            <uri>file:///home/aerobase/drone_model/src/drone_description_backup/meshes/rotor1.STL</uri>
          </mesh>
        </geometry>
        <material>
          <diffuse>0 0 1 1</diffuse>
          <ambient>0 0 1 1</ambient>
        </material>
      </visual>
      <visual name='base_link_fixed_joint_lump__front_right_visual_2'>
        <pose>0.2 -0.2 0 0 0 0</pose>
        <geometry>
          <mesh>
            <scale>0.5 0.5 0.5</scale>
            <uri>file:///home/aerobase/drone_model/src/drone_description_backup/meshes/rotor2.STL</uri>
          </mesh>
        </geometry>
        <material>
          <diffuse>0 0 1 1</diffuse>
          <ambient>0 0 1 1</ambient>
        </material>
      </visual>
      <visual name='base_link_fixed_joint_lump__rear_left_visual_3'>
        <pose>-0.2 0.2 0 0 0 0</pose>
        <geometry>
          <mesh>
            <scale>0.5 0.5 0.5</scale>
            <uri>file:///home/aerobase/drone_model/src/drone_description_backup/meshes/rotor3.STL</uri>
          </mesh>
        </geometry>
        <material>
          <diffuse>0 0 1 1</diffuse>
          <ambient>0 0 1 1</ambient>
        </material>
      </visual>
      <visual name='base_link_fixed_joint_lump__rear_right_visual_4'>
        <pose>-0.2 -0.2 0 0 0 0</pose>
        <geometry>
          <mesh>
            <scale>0.5 0.5 0.5</scale>
            <uri>file:///home/aerobase/drone_model/src/drone_description_backup/meshes/rotor4.STL</uri>
          </mesh>
        </geometry>
        <material>
          <diffuse>0 0 1 1</diffuse>
          <ambient>0 0 1 1</ambient>
        </material>
      </visual>
    </link>

    <!-- Arm joints -->
    <frame name='front_left_joint' attached_to='base_link'>
      <pose>0.20000000000000001 0.20000000000000001 0.050000000000000003 0 0 0</pose>
    </frame>
    <frame name='front_left' attached_to='front_left_joint'>
      <pose>0 0 0 0 0 0</pose>
    </frame>
    <frame name='front_right_joint' attached_to='base_link'>
      <pose>0.20000000000000001 -0.20000000000000001 0.050000000000000003 0 0 0</pose>
    </frame>
    <frame name='front_right' attached_to='front_right_joint'>
      <pose>0 0 0 0 0 0</pose>
    </frame>
    <frame name='rear_left_joint' attached_to='base_link'>
      <pose>-0.20000000000000001 0.20000000000000001 0.050000000000000003 0 0 0</pose>
    </frame>
    <frame name='rear_left' attached_to='rear_left_joint'>
      <pose>0 0 0 0 0 0</pose>
    </frame>
    <frame name='rear_right_joint' attached_to='base_link'>
      <pose>-0.20000000000000001 -0.20000000000000001 0.050000000000000003 0 0 0</pose>
    </frame>
    <frame name='rear_right' attached_to='rear_right_joint'>
      <pose>0 0 0 0 0 0</pose>
    </frame>
    
    <!-- Propeller -->
     <!-- motor 3 cw front left -->
    <link name="motor3_fl_link">
      <pose relative_to="motor3_fl_joint">0 0 0 0 0 0</pose>
      <inertial>
        <mass>0.025</mass>
        <inertia>
          <ixx>9.75e-06</ixx>
          <ixy>0</ixy>
          <ixz>0</ixz>
          <iyy>0.000166704</iyy>
          <iyz>0</iyz>
          <izz>0.000167604</izz>
        </inertia>
      </inertial>
      <collision name="collision">
        <geometry>
          <cylinder>
            <length>0.005</length>
            <radius>0.07</radius>
          </cylinder>
        </geometry>
      </collision>
      <visual name="visual">
        <geometry>
          <mesh>
            <scale>0.7 0.7 0.7</scale>
            <uri>model://hexapod_copter/meshes/iris_prop_cw.dae</uri>
          </mesh>
        </geometry>
        <material>
          <ambient>0 1 0</ambient>
          <diffuse>0 1 0</diffuse>
          <specular>0.1 0.1 0.1 1</specular>
        </material>
      </visual>
    </link>
    <joint name="motor3_fl_joint" type="revolute">
      <pose relative_to="tibia_fl_link">0.03 0 -0.03 0 1.570796 0</pose>
      <child>motor3_fl_link</child>
      <parent>tibia_fl_link</parent>
      <axis>
        <xyz>0 0 1</xyz>
        <limit>
          <lower>-1e+16</lower>
          <upper>1e+16</upper>
        </limit>
        <dynamics>
          <damping>0.004</damping>
        </dynamics>
      </axis>
    </joint>

    <!-- motor 5 ccw front right -->
    <link name="motor5_fr_link">
      <pose relative_to="motor5_fr_joint">0 0 0 0 0 0</pose>
      <inertial>
        <mass>0.025</mass>
        <inertia>
          <ixx>9.75e-06</ixx>
          <ixy>0</ixy>
          <ixz>0</ixz>
          <iyy>0.000166704</iyy>
          <iyz>0</iyz>
          <izz>0.000167604</izz>
        </inertia>
      </inertial>
      <collision name="collision">
        <geometry>
          <cylinder>
            <length>0.005</length>
            <radius>0.07</radius>
          </cylinder>
        </geometry>
      </collision>
      <visual name="visual">
        <geometry>
          <mesh>
            <scale>0.7 0.7 0.7</scale>
            <uri>model://hexapod_copter/meshes/iris_prop_ccw.dae</uri>
          </mesh>
        </geometry>
        <material>
          <ambient>0 0 1</ambient>
          <diffuse>0 0 1</diffuse>
          <specular>0.1 0.1 0.1 1</specular>
        </material>
      </visual>
    </link>
    <joint name="motor5_fr_joint" type="revolute">
      <pose relative_to="tibia_fr_link">0.03 0 -0.03 0 1.570796 0</pose>
      <child>motor5_fr_link</child>
      <parent>tibia_fr_link</parent>
      <axis>
        <xyz>0 0 1</xyz>
        <limit>
          <lower>-1e+16</lower>
          <upper>1e+16</upper>
        </limit>
        <dynamics>
          <damping>0.004</damping>
        </dynamics>
      </axis>
    </joint>

    <!-- motor 6 cw back left -->
    <link name="motor6_bl_link">
      <pose relative_to="motor6_bl_joint">0 0 0 0 0 0</pose>
      <inertial>
        <mass>0.025</mass>
        <inertia>
          <ixx>9.75e-06</ixx>
          <ixy>0</ixy>
          <ixz>0</ixz>
          <iyy>0.000166704</iyy>
          <iyz>0</iyz>
          <izz>0.000167604</izz>
        </inertia>
      </inertial>
      <collision name="collision">
        <geometry>
          <cylinder>
            <length>0.005</length>
            <radius>0.07</radius>
          </cylinder>
        </geometry>
      </collision>
      <visual name="visual">
        <geometry>
          <mesh>
            <scale>0.7 0.7 0.7</scale>
            <uri>model://hexapod_copter/meshes/iris_prop_cw.dae</uri>
          </mesh>
        </geometry>
        <material>
          <ambient>0 1 0</ambient>
          <diffuse>0 1 0</diffuse>
          <specular>0.1 0.1 0.1 1</specular>
        </material>
      </visual>
    </link>
    <joint name="motor6_bl_joint" type="revolute">
      <pose relative_to="tibia_bl_link">0.03 0 -0.03 0 1.570796 0</pose>
      <child>motor6_bl_link</child>
      <parent>tibia_bl_link</parent>
      <axis>
        <xyz>0 0 1</xyz>
        <limit>
          <lower>-1e+16</lower>
          <upper>1e+16</upper>
        </limit>
        <dynamics>
          <damping>0.004</damping>
        </dynamics>
      </axis>
    </joint>

    <!-- motor 4 ccw back right -->
    <link name="motor4_br_link">
      <pose relative_to="motor4_br_joint">0 0 0 0 0 0</pose>
      <inertial>
        <mass>0.025</mass>
        <inertia>
          <ixx>9.75e-06</ixx>
          <ixy>0</ixy>
          <ixz>0</ixz>
          <iyy>0.000166704</iyy>
          <iyz>0</iyz>
          <izz>0.000167604</izz>
        </inertia>
      </inertial>
      <collision name="collision">
        <geometry>
          <cylinder>
            <length>0.005</length>
            <radius>0.07</radius>
          </cylinder>
        </geometry>
      </collision>
      <visual name="visual">
        <geometry>
          <mesh>
            <scale>0.7 0.7 0.7</scale>
            <uri>model://hexapod_copter/meshes/iris_prop_ccw.dae</uri>
          </mesh>
        </geometry>
        <material>
          <ambient>0 0 1</ambient>
          <diffuse>0 0 1</diffuse>
          <specular>0.1 0.1 0.1 1</specular>
        </material>
      </visual>
    </link>
    <joint name="motor4_br_joint" type="revolute">
      <pose relative_to="tibia_br_link">0.03 0 -0.03 0 1.570796 0</pose>
      <child>motor4_br_link</child>
      <parent>tibia_br_link</parent>
      <axis>
        <xyz>0 0 1</xyz>
        <limit>
          <lower>-1e+16</lower>
          <upper>1e+16</upper>
        </limit>
        <dynamics>
          <damping>0.004</damping>
        </dynamics>
      </axis>
    </joint>

    <!-- motor 2 ccw mid left -->
    <link name="motor2_ml_link">
      <pose relative_to="motor2_ml_joint">0 0 0 0 0 0</pose>
      <inertial>
        <mass>0.025</mass>
        <inertia>
          <ixx>9.75e-06</ixx>
          <ixy>0</ixy>
          <ixz>0</ixz>
          <iyy>0.000166704</iyy>
          <iyz>0</iyz>
          <izz>0.000167604</izz>
        </inertia>
      </inertial>
      <collision name="collision">
        <geometry>
          <cylinder>
            <length>0.005</length>
            <radius>0.07</radius>
          </cylinder>
        </geometry>
      </collision>
      <visual name="visual">
        <geometry>
          <mesh>
            <scale>0.7 0.7 0.7</scale>
            <uri>model://hexapod_copter/meshes/iris_prop_ccw.dae</uri>
          </mesh>
        </geometry>
        <material>
          <ambient>0 0 1</ambient>
          <diffuse>0 0 1</diffuse>
          <specular>0.1 0.1 0.1 1</specular>
        </material>
      </visual>
    </link>
    <joint name="motor2_ml_joint" type="revolute">
      <pose relative_to="tibia_ml_link">0.03 0 -0.03 0 1.570796 0</pose>
      <child>motor2_ml_link</child>
      <parent>tibia_ml_link</parent>
      <axis>
        <xyz>0 0 1</xyz>
        <limit>
          <lower>-1e+16</lower>
          <upper>1e+16</upper>
        </limit>
        <dynamics>
          <damping>0.004</damping>
        </dynamics>
      </axis>
    </joint>

    <!-- motor 1 cw mid right -->
    <link name="motor1_mr_link">
      <pose relative_to="motor1_mr_joint">0 0 0 0 0 0</pose>
      <inertial>
        <mass>0.025</mass>
        <inertia>
          <ixx>9.75e-06</ixx>
          <ixy>0</ixy>
          <ixz>0</ixz>
          <iyy>0.000166704</iyy>
          <iyz>0</iyz>
          <izz>0.000167604</izz>
        </inertia>
      </inertial>
      <collision name="collision">
        <geometry>
          <cylinder>
            <length>0.005</length>
            <radius>0.07</radius>
          </cylinder>
        </geometry>
      </collision>
      <visual name="visual">
        <geometry>
          <mesh>
            <scale>0.7 0.7 0.7</scale>
            <uri>model://hexapod_copter/meshes/iris_prop_cw.dae</uri>
          </mesh>
        </geometry>
        <material>
          <ambient>0 1 0</ambient>
          <diffuse>0 1 0</diffuse>
          <specular>0.1 0.1 0.1 1</specular>
        </material>
      </visual>
    </link>
    <joint name="motor1_mr_joint" type="revolute">
      <pose relative_to="tibia_mr_link">0.03 0 -0.03 0 1.570796 0</pose>
      <child>motor1_mr_link</child>
      <parent>tibia_mr_link</parent>
      <axis>
        <xyz>0 0 1</xyz>
        <limit>
          <lower>-1e+16</lower>
          <upper>1e+16</upper>
        </limit>
        <dynamics>
          <damping>0.004</damping>
        </dynamics>
      </axis>
    </joint>
    
    <!-- Gimbal inclusion -->
    <include>
      <uri>model://gimbal_small_3d</uri>
      <name>gimbal</name>
      <pose degrees="true">0 -0.01 -0.124923 90 0 90</pose>
    </include>

    <joint name="gimbal_joint" type="revolute">
      <parent>quadcopter::base_link</parent>
      <child>gimbal::base_link</child>
      <axis>
        <limit>
          <lower>0</lower>
          <upper>0</upper>
        </limit>
        <xyz>0 0 1</xyz>
      </axis>
    </joint>

    <!-- Gimbal joint position controllers -->
    <plugin filename="gz-sim-joint-position-controller-system" name="gz::sim::systems::JointPositionController">
      <joint_name>gimbal::roll_joint</joint_name>
      <topic>/gimbal/cmd_roll</topic>
      <p_gain>2</p_gain>
    </plugin>

    <plugin filename="gz-sim-joint-position-controller-system" name="gz::sim::systems::JointPositionController">
      <joint_name>gimbal::pitch_joint</joint_name>
      <topic>/gimbal/cmd_pitch</topic>
      <p_gain>2</p_gain>
    </plugin>

    <plugin filename="gz-sim-joint-position-controller-system" name="gz::sim::systems::JointPositionController">
      <joint_name>gimbal::yaw_joint</joint_name>
      <topic>/gimbal/cmd_yaw</topic>
      <p_gain>2</p_gain>
    </plugin>

  </model>
</sdf>
