<sdf version='1.11'>
  <model name='hexadrone'>
    <link name="base_link">
      <inertial>
        <pose>0 0 0.25 -1.585 0 0</pose>
        <mass>0.5</mass>
        <inertia>
          <ixx>0.10000000000000001</ixx>
          <ixy>0</ixy>
          <ixz>0</ixz>
          <iyy>0.10000000000000001</iyy>
          <iyz>0</iyz>
          <izz>0.10000000000000001</izz>
        </inertia>
      </inertial>
      <visual name="visual">
        <pose>0 0 0.25 -1.585 0 0</pose>
        <geometry>
          <mesh>
            <uri>file:///home/aerobase/hexadrone/models/hexadrone_model/meshes/base_link.STL</uri>
          </mesh>
        </geometry>
      </visual>

      <collision name="base_link_collision">
        <pose>0 0 0.25 -1.585 0 0</pose>
        <geometry>
          <mesh>
            <scale>1 1 1</scale>
            <uri>file:///home/aerobase/hexadrone/models/hexadrone_model/meshes/base_link.STL</uri>
          </mesh>
        </geometry>
      </collision>
    </link>

    <!-- sensors -->
    <link name="gps_sensor_link">
      <inertial>
        <pose>0 0 0 0 0 0</pose>
        <mass>0.15</mass>
        <inertia>
          <ixx>0.00002</ixx>
          <ixy>0</ixy>
          <ixz>0</ixz>
          <iyy>0.00002</iyy>
          <iyz>0</iyz>
          <izz>0.00002</izz>
        </inertia>
      </inertial>
      <!-- GPS sensor -->
      <sensor name="gps_sensor" type="gps">
        <pose>0 0 0 0 0 0</pose>
        <update_rate>5</update_rate>
        <gps>
          <position_sensing>
            <horizontal>
              <noise type="gaussian">
                <mean>0.0</mean>
                <stddev>0.01</stddev>
              </noise>
            </horizontal>
            <vertical>
              <noise type="gaussian">
                <mean>0.0</mean>
                <stddev>0.01</stddev>
              </noise>
            </vertical>
          </position_sensing>
        </gps>
      </sensor>
    </link>

    <!-- sensors -->
    <link name="imu_link">
      <inertial>
        <pose>0 0 0 0 0 0</pose>
        <mass>0.15</mass>
        <inertia>
          <ixx>0.00002</ixx>
          <ixy>0</ixy>
          <ixz>0</ixz>
          <iyy>0.00002</iyy>
          <iyz>0</iyz>
          <izz>0.00002</izz>
        </inertia>
      </inertial>
      <sensor name="imu_sensor" type="imu">
        <pose>0 0 0 3.141593 0 0</pose>
        <always_on>1</always_on>
        <update_rate>600.0</update_rate>
      </sensor>
    </link>

    <joint name="imu_joint" type="revolute">
      <child>imu_link</child>
      <parent>base_link</parent>
      <axis>
        <xyz>0 0 1</xyz>
        <limit>
          <lower>-1e16</lower>
          <upper>1e16</upper>
          <effort>10</effort>
          <velocity>100</velocity>
        </limit>
        <dynamics>
          <damping>1.0</damping>
        </dynamics>
        <use_parent_model_frame>1</use_parent_model_frame>
      </axis>
    </joint>
    
    <!-- Propeller -->
     <!-- motor 3 cw front left -->
    <link name="motor3_fl_link">
      <pose relative_to="motor3_fl_joint">0 0 0 0 0 0</pose>
      <inertial>
        <mass>0.025</mass>
        <inertia>
          <ixx>9.75e-06</ixx>
          <ixy>0</ixy>
          <ixz>0</ixz>
          <iyy>0.000166704</iyy>
          <iyz>0</iyz>
          <izz>0.000167604</izz>
        </inertia>
      </inertial>
      <collision name="collision">
        <geometry>
          <cylinder>
            <length>0.01</length>
            <radius>0.07</radius>
          </cylinder>
        </geometry>
      </collision>
      <visual name="visual">
        <geometry>
          <mesh>
            <scale>0.7 0.7 0.7</scale>
            <uri>file:///home/aerobase/hexadrone/models/hexadrone_model/meshes/iris_prop_cw.dae</uri>
          </mesh>
        </geometry>
        <material>
          <ambient>0 1 0</ambient>
          <diffuse>0 1 0</diffuse>
          <specular>0.1 0.1 0.1 1</specular>
        </material>
      </visual>
    </link>
    <joint name="motor3_fl_joint" type="revolute">
      <pose relative_to="base_link">-0.121 0.262 0.3 0 0 0</pose>
      <child>motor3_fl_link</child>
      <parent>base_link</parent>
      <axis>
        <xyz>0 0 1</xyz>
        <limit>
          <lower>-1e16</lower>
          <upper>1e16</upper>
          <effort>10</effort>
          <velocity>100</velocity>
        </limit>
        <dynamics>
          <damping>1.0</damping>
        </dynamics>
      </axis>
    </joint>

    <!-- motor 5 ccw front right -->
    <link name="motor5_fr_link">
      <pose relative_to="motor5_fr_joint">0 0 0 0 0 0</pose>
      <inertial>
        <mass>0.025</mass>
        <inertia>
          <ixx>9.75e-06</ixx>
          <ixy>0</ixy>
          <ixz>0</ixz>
          <iyy>0.000166704</iyy>
          <iyz>0</iyz>
          <izz>0.000167604</izz>
        </inertia>
      </inertial>
      <collision name="collision">
        <geometry>
          <cylinder>
            <length>0.01</length>
            <radius>0.07</radius>
          </cylinder>
        </geometry>
      </collision>
      <visual name="visual">
        <geometry>
          <mesh>
            <scale>0.7 0.7 0.7</scale>
            <uri>file:///home/aerobase/hexadrone/models/hexadrone_model/meshes/iris_prop_ccw.dae</uri>
          </mesh>
        </geometry>
        <material>
          <ambient>0 0 1</ambient>
          <diffuse>0 0 1</diffuse>
          <specular>0.1 0.1 0.1 1</specular>
        </material>
      </visual>
    </link>
    <joint name="motor5_fr_joint" type="revolute">
      <pose relative_to="base_link">0.167 0.261 0.3 0 0 0</pose>
      <child>motor5_fr_link</child>
      <parent>base_link</parent>
      <axis>
        <xyz>0 0 1</xyz>
        <limit>
          <lower>-1e16</lower>
          <upper>1e16</upper>
          <effort>10</effort>
          <velocity>100</velocity>
        </limit>
        <dynamics>
          <damping>1.0</damping>
        </dynamics>
      </axis>
    </joint>

    <!-- motor 6 cw back left -->
    <link name="motor6_bl_link">
      <pose relative_to="motor6_bl_joint">0 0 0 0 0 0</pose>
      <inertial>
        <mass>0.025</mass>
        <inertia>
          <ixx>9.75e-06</ixx>
          <ixy>0</ixy>
          <ixz>0</ixz>
          <iyy>0.000166704</iyy>
          <iyz>0</iyz>
          <izz>0.000167604</izz>
        </inertia>
      </inertial>
      <collision name="collision">
        <geometry>
          <cylinder>
            <length>0.01</length>
            <radius>0.07</radius>
          </cylinder>
        </geometry>
      </collision>
      <visual name="visual">
        <geometry>
          <mesh>
            <scale>0.7 0.7 0.7</scale>
            <uri>file:///home/aerobase/hexadrone/models/hexadrone_model/meshes/iris_prop_cw.dae</uri>
          </mesh>
        </geometry>
        <material>
          <ambient>0 1 0</ambient>
          <diffuse>0 1 0</diffuse>
          <specular>0.1 0.1 0.1 1</specular>
        </material>
      </visual>
    </link>
    <joint name="motor6_bl_joint" type="revolute">
      <pose relative_to="base_link">-0.121 -0.23 0.3 0 0 0</pose>
      <child>motor6_bl_link</child>
      <parent>base_link</parent>
      <axis>
        <xyz>0 0 1</xyz>
        <limit>
          <lower>-1e16</lower>
          <upper>1e16</upper>
          <effort>10</effort>
          <velocity>100</velocity>
        </limit>
        <dynamics>
          <damping>1.0</damping>
        </dynamics>
      </axis>
    </joint>

    <!-- motor 4 ccw back right -->
    <link name="motor4_br_link">
      <pose relative_to="motor4_br_joint">0 0 0 0 0 0</pose>
      <inertial>
        <mass>0.025</mass>
        <inertia>
          <ixx>9.75e-06</ixx>
          <ixy>0</ixy>
          <ixz>0</ixz>
          <iyy>0.000166704</iyy>
          <iyz>0</iyz>
          <izz>0.000167604</izz>
        </inertia>
      </inertial>
      <collision name="collision">
        <geometry>
          <cylinder>
            <length>0.01</length>
            <radius>0.07</radius>
          </cylinder>
        </geometry>
      </collision>
      <visual name="visual">
        <geometry>
          <mesh>
            <scale>0.7 0.7 0.7</scale>
            <uri>file:///home/aerobase/hexadrone/models/hexadrone_model/meshes/iris_prop_ccw.dae</uri>
          </mesh>
        </geometry>
        <material>
          <ambient>0 0 1</ambient>
          <diffuse>0 0 1</diffuse>
          <specular>0.1 0.1 0.1 1</specular>
        </material>
      </visual>
    </link>
    <joint name="motor4_br_joint" type="revolute">
      <pose relative_to="base_link">0.167 -0.23 0.3 0 0 0</pose>
      <child>motor4_br_link</child>
      <parent>base_link</parent>
      <axis>
        <xyz>0 0 1</xyz>
        <limit>
          <lower>-1e16</lower>
          <upper>1e16</upper>
          <effort>10</effort>
          <velocity>100</velocity>
        </limit>
        <dynamics>
          <damping>1.0</damping>
        </dynamics>
      </axis>
    </joint>

    <!-- motor 2 ccw mid left -->
    <link name="motor2_ml_link">
      <pose relative_to="motor2_ml_joint">0 0 0 0 0 0</pose>
      <inertial>
        <mass>0.025</mass>
        <inertia>
          <ixx>9.75e-06</ixx>
          <ixy>0</ixy>
          <ixz>0</ixz>
          <iyy>0.000166704</iyy>
          <iyz>0</iyz>
          <izz>0.000167604</izz>
        </inertia>
      </inertial>
      <collision name="collision">
        <geometry>
          <cylinder>
            <length>0.01</length>
            <radius>0.07</radius>
          </cylinder>
        </geometry>
      </collision>
      <visual name="visual">
        <geometry>
          <mesh>
            <scale>0.7 0.7 0.7</scale>
            <uri>file:///home/aerobase/hexadrone/models/hexadrone_model/meshes/iris_prop_ccw.dae</uri>
          </mesh>
        </geometry>
        <material>
          <ambient>0 0 1</ambient>
          <diffuse>0 0 1</diffuse>
          <specular>0.1 0.1 0.1 1</specular>
        </material>
      </visual>
    </link>
    <joint name="motor2_ml_joint" type="revolute">
      <pose relative_to="base_link">-0.262 0.0151 0.3 0 0 0</pose>
      <child>motor2_ml_link</child>
      <parent>base_link</parent>
      <axis>
        <xyz>0 0 1</xyz>
        <limit>
          <lower>-1e16</lower>
          <upper>1e16</upper>
          <effort>10</effort>
          <velocity>100</velocity>
        </limit>
        <dynamics>
          <damping>1.0</damping>
        </dynamics>
      </axis>
    </joint>

    <!-- motor 1 cw mid right -->
    <link name="motor1_mr_link">
      <pose relative_to="motor1_mr_joint">0 0 0 0 0 0</pose>
      <inertial>
        <mass>0.025</mass>
        <inertia>
          <ixx>9.75e-06</ixx>
          <ixy>0</ixy>
          <ixz>0</ixz>
          <iyy>0.000166704</iyy>
          <iyz>0</iyz>
          <izz>0.000167604</izz>
        </inertia>
      </inertial>
      <collision name="collision">
        <geometry>
          <cylinder>
            <length>0.01</length>
            <radius>0.07</radius>
          </cylinder>
        </geometry>
      </collision>
      <visual name="visual">
        <geometry>
          <mesh>
            <scale>0.7 0.7 0.7</scale>
            <uri>file:///home/aerobase/hexadrone/models/hexadrone_model/meshes/iris_prop_cw.dae</uri>
          </mesh>
        </geometry>
        <material>
          <ambient>0 1 0</ambient>
          <diffuse>0 1 0</diffuse>
          <specular>0.1 0.1 0.1 1</specular>
        </material>
      </visual>
    </link>
    <joint name="motor1_mr_joint" type="revolute">
      <pose relative_to="base_link">0.306 0.0145 0.3 0 0 0</pose>
      <child>motor1_mr_link</child>
      <parent>base_link</parent>
      <axis>
        <xyz>0 0 1</xyz>
        <limit>
          <lower>-1e16</lower>
          <upper>1e16</upper>
          <effort>10</effort>
          <velocity>100</velocity>
        </limit>
        <dynamics>
          <damping>1.0</damping>
        </dynamics>
      </axis>
    </joint>

    <plugin name="ArduPilotPlugin" filename="ArduPilotPlugin">
      <!-- Communication -->
      <fdm_addr>127.0.0.1</fdm_addr>
      <fdm_port_in>9002</fdm_port_in>
      <connectionTimeoutMaxCount>5</connectionTimeoutMaxCount>
      <lock_step>1</lock_step>
      <have_32_channels>1</have_32_channels>
       <!-- Transforms -->
      <gazeboXYZToNED>0 0 0 3.141593 0 1.57079632</gazeboXYZToNED>
      <modelXYZToAirplaneXForwardZDown>0 0 0 3.141593 0 0</modelXYZToAirplaneXForwardZDown>

      <!-- Sensors -->
      <imuName>imu_link::imu_sensor</imuName>

      <!-- Velocity control -->
      <!-- 
        ccw:  positive multiplier
        cw:   negative multiplier
      -->
      <!-- 
          SERVO1_FUNCTION 33 (Motor1)
          SERVO1_MAX        2000
          SERVO1_MIN        1000
          SERVO1_REVERSED      0
          SERVO1_TRIM       1500
      -->
      <!-- motor 1 cw -->
      <control channel="0">
        <jointName>motor1_mr_joint</jointName>
        <useForce>1</useForce>
        <multiplier>-60000.0</multiplier>
        <offset>0</offset>
        <servo_min>1000</servo_min>
        <servo_max>2000</servo_max>
        <type>VELOCITY</type>
        <p_gain>0.20</p_gain>
        <i_gain>0</i_gain>
        <d_gain>0</d_gain>
        <i_max>1</i_max>
        <i_min>-1</i_min>
        <cmd_max>1.0</cmd_max>
        <cmd_min>0.0</cmd_min>
      </control>

      <!-- 
          SERVO2_FUNCTION 34 (Motor2)
      -->
      <!-- motor 2 ccw -->
      <control channel="1">
        <jointName>motor2_ml_joint</jointName>
        <useForce>1</useForce>
        <multiplier>60000.0</multiplier>
        <offset>0</offset>
        <servo_min>1000</servo_min>
        <servo_max>2000</servo_max>
        <type>VELOCITY</type>
        <p_gain>0.20</p_gain>
        <i_gain>0</i_gain>
        <d_gain>0</d_gain>
        <i_max>1</i_max>
        <i_min>-1</i_min>
        <cmd_max>1.0</cmd_max>
        <cmd_min>0.0</cmd_min>
      </control>

      <!-- 
          SERVO3_FUNCTION 35 (Motor3)
      -->
      <!-- motor 3 cw -->
      <control channel="2">
        <jointName>motor3_fl_joint</jointName>
        <useForce>1</useForce>
        <multiplier>-60000.0</multiplier>
        <offset>0</offset>
        <servo_min>1000</servo_min>
        <servo_max>2000</servo_max>
        <type>VELOCITY</type>
        <p_gain>0.20</p_gain>
        <i_gain>0</i_gain>
        <d_gain>0</d_gain>
        <i_max>1</i_max>
        <i_min>-1</i_min>
        <cmd_max>1.0</cmd_max>
        <cmd_min>0.0</cmd_min>
      </control>

      <!-- 
          SERVO4_FUNCTION 36 (Motor4)
      -->
      <!-- motor 4 ccw -->
      <control channel="3">
        <jointName>motor4_br_joint</jointName>
        <useForce>1</useForce>
        <multiplier>60000.0</multiplier>
        <offset>0</offset>
        <servo_min>1000</servo_min>
        <servo_max>2000</servo_max>
        <type>VELOCITY</type>
        <p_gain>0.20</p_gain>
        <i_gain>0</i_gain>
        <d_gain>0</d_gain>
        <i_max>1</i_max>
        <i_min>-1</i_min>
        <cmd_max>1.0</cmd_max>
        <cmd_min>0.0</cmd_min>
      </control>

      <!-- 
          SERVO5_FUNCTION 37 (Motor5)
      -->
      <!-- motor 5 ccw -->
      <control channel="4">
        <jointName>motor5_fr_joint</jointName>
        <useForce>1</useForce>
        <multiplier>60000.0</multiplier>
        <offset>0</offset>
        <servo_min>1000</servo_min>
        <servo_max>2000</servo_max>
        <type>VELOCITY</type>
        <p_gain>0.20</p_gain>
        <i_gain>0</i_gain>
        <d_gain>0</d_gain>
        <i_max>1</i_max>
        <i_min>-1</i_min>
        <cmd_max>1.0</cmd_max>
        <cmd_min>0.0</cmd_min>
      </control>

      <!-- 
          SERVO6_FUNCTION 38 (Motor6)
      -->
      <!-- motor 6 cw -->
      <control channel="5">
        <jointName>motor6_bl_joint</jointName>
        <useForce>1</useForce>
        <multiplier>-60000.0</multiplier>
        <offset>0</offset>
        <servo_min>1000</servo_min>
        <servo_max>2000</servo_max>
        <type>VELOCITY</type>
        <p_gain>0.20</p_gain>
        <i_gain>0</i_gain>
        <d_gain>0</d_gain>
        <i_max>1</i_max>
        <i_min>-1</i_min>
        <cmd_max>1.0</cmd_max>
        <cmd_min>0.0</cmd_min>
      </control>

      </plugin>


  </model>
</sdf>
