<sdf version='1.11'>
  <model name='quadcopter'>
    <link name='base_link'>
      <inertial>
        <pose>0 0 0.25 -1.585 0 0</pose>
        <mass>1.5</mass>
        <inertia>
          <ixx>0.10000000000000001</ixx>
          <ixy>0</ixy>
          <ixz>0</ixz>
          <iyy>0.10000000000000001</iyy>
          <iyz>0</iyz>
          <izz>0.10000000000000001</izz>
        </inertia>
      </inertial>
      <visual name="visual">
        <pose>0 0 0.25 -1.585 0 0</pose>
        <geometry>
          <mesh>
            <uri>file:///home/aerobase/hexadrone/models/hexadrone_model/meshes/base_link.STL</uri>
          </mesh>
        </geometry>
      </visual>

      <collision name='base_link_collision'>
        <pose>0 0 0.25 -1.585 0 0</pose>
        <geometry>
          <mesh>
            <scale>1 1 1</scale>
            <uri>file:///home/aerobase/hexadrone/models/hexadrone_model/meshes/base_link.STL</uri>
          </mesh>
        </geometry>
      </collision>
    </link>

    <!-- sensors -->
    <link name="imu_link">
      <inertial>
        <pose>0 0 0 0 0 0</pose>
        <mass>0.15</mass>
        <inertia>
          <ixx>0.00002</ixx>
          <ixy>0</ixy>
          <ixz>0</ixz>
          <iyy>0.00002</iyy>
          <iyz>0</iyz>
          <izz>0.00002</izz>
        </inertia>
      </inertial>
      <sensor name="imu_sensor" type="imu">
        <pose>0 0 0 3.141593 0 0</pose>
        <always_on>1</always_on>
        <update_rate>1000.0</update_rate>
      </sensor>
    </link>
    <joint name="imu_joint" type="revolute">
      <child>imu_link</child>
      <parent>base_link</parent>
      <axis>
        <xyz>0 0 1</xyz>
        <limit>
          <lower>0</lower>
          <upper>0</upper>
          <effort>0</effort>
          <velocity>0</velocity>
        </limit>
        <dynamics>
          <damping>1.0</damping>
        </dynamics>
        <use_parent_model_frame>1</use_parent_model_frame>
      </axis>
    </joint>
    
    <!-- Propeller -->
     <!-- motor 3 cw front left -->
    <link name="motor3_fl_link">
      <pose relative_to="motor3_fl_joint">0 0 0 0 0 0</pose>
      <inertial>
        <mass>0.025</mass>
        <inertia>
          <ixx>9.75e-06</ixx>
          <ixy>0</ixy>
          <ixz>0</ixz>
          <iyy>0.000166704</iyy>
          <iyz>0</iyz>
          <izz>0.000167604</izz>
        </inertia>
      </inertial>
      <collision name="collision">
        <geometry>
          <cylinder>
            <length>0.005</length>
            <radius>0.07</radius>
          </cylinder>
        </geometry>
      </collision>
      <visual name="visual">
        <geometry>
          <mesh>
            <scale>0.7 0.7 0.7</scale>
            <uri>file:///home/aerobase/hexadrone/models/hexadrone_model/meshes/iris_prop_cw.dae</uri>
          </mesh>
        </geometry>
        <material>
          <ambient>0 1 0</ambient>
          <diffuse>0 1 0</diffuse>
          <specular>0.1 0.1 0.1 1</specular>
        </material>
      </visual>
    </link>
    <joint name="motor3_fl_joint" type="revolute">
      <pose relative_to="base_link">0 0 0.05 -1.585 0 0</pose>
      <child>motor3_fl_link</child>
      <parent>base_link</parent>
      <axis>
        <xyz>0 0 1</xyz>
        <limit>
          <lower>-1e+16</lower>
          <upper>1e+16</upper>
        </limit>
        <dynamics>
          <damping>0.004</damping>
        </dynamics>
      </axis>
    </joint>

    <!-- motor 5 ccw front right -->
    <link name="motor5_fr_link">
      <pose relative_to="motor5_fr_joint">0 0 0 0 0 0</pose>
      <inertial>
        <mass>0.025</mass>
        <inertia>
          <ixx>9.75e-06</ixx>
          <ixy>0</ixy>
          <ixz>0</ixz>
          <iyy>0.000166704</iyy>
          <iyz>0</iyz>
          <izz>0.000167604</izz>
        </inertia>
      </inertial>
      <collision name="collision">
        <geometry>
          <cylinder>
            <length>0.005</length>
            <radius>0.07</radius>
          </cylinder>
        </geometry>
      </collision>
      <visual name="visual">
        <geometry>
          <mesh>
            <scale>0.7 0.7 0.7</scale>
            <uri>file:///home/aerobase/hexadrone/models/hexadrone_model/meshes/iris_prop_ccw.dae</uri>
          </mesh>
        </geometry>
        <material>
          <ambient>0 0 1</ambient>
          <diffuse>0 0 1</diffuse>
          <specular>0.1 0.1 0.1 1</specular>
        </material>
      </visual>
    </link>
    <joint name="motor5_fr_joint" type="revolute">
      <pose relative_to="base_link">0.03 0 -0.03 0 1.570796 0</pose>
      <child>motor5_fr_link</child>
      <parent>base_link</parent>
      <axis>
        <xyz>0 0 1</xyz>
        <limit>
          <lower>-1e+16</lower>
          <upper>1e+16</upper>
        </limit>
        <dynamics>
          <damping>0.004</damping>
        </dynamics>
      </axis>
    </joint>

    <!-- motor 6 cw back left -->
    <link name="motor6_bl_link">
      <pose relative_to="motor6_bl_joint">0 0 0 0 0 0</pose>
      <inertial>
        <mass>0.025</mass>
        <inertia>
          <ixx>9.75e-06</ixx>
          <ixy>0</ixy>
          <ixz>0</ixz>
          <iyy>0.000166704</iyy>
          <iyz>0</iyz>
          <izz>0.000167604</izz>
        </inertia>
      </inertial>
      <collision name="collision">
        <geometry>
          <cylinder>
            <length>0.005</length>
            <radius>0.07</radius>
          </cylinder>
        </geometry>
      </collision>
      <visual name="visual">
        <geometry>
          <mesh>
            <scale>0.7 0.7 0.7</scale>
            <uri>file:///home/aerobase/hexadrone/models/hexadrone_model/meshes/iris_prop_cw.dae</uri>
          </mesh>
        </geometry>
        <material>
          <ambient>0 1 0</ambient>
          <diffuse>0 1 0</diffuse>
          <specular>0.1 0.1 0.1 1</specular>
        </material>
      </visual>
    </link>
    <joint name="motor6_bl_joint" type="revolute">
      <pose relative_to="base_link">0.03 0 -0.03 0 1.570796 0</pose>
      <child>motor6_bl_link</child>
      <parent>base_link</parent>
      <axis>
        <xyz>0 0 1</xyz>
        <limit>
          <lower>-1e+16</lower>
          <upper>1e+16</upper>
        </limit>
        <dynamics>
          <damping>0.004</damping>
        </dynamics>
      </axis>
    </joint>

    <!-- motor 4 ccw back right -->
    <link name="motor4_br_link">
      <pose relative_to="motor4_br_joint">0 0 0 0 0 0</pose>
      <inertial>
        <mass>0.025</mass>
        <inertia>
          <ixx>9.75e-06</ixx>
          <ixy>0</ixy>
          <ixz>0</ixz>
          <iyy>0.000166704</iyy>
          <iyz>0</iyz>
          <izz>0.000167604</izz>
        </inertia>
      </inertial>
      <collision name="collision">
        <geometry>
          <cylinder>
            <length>0.005</length>
            <radius>0.07</radius>
          </cylinder>
        </geometry>
      </collision>
      <visual name="visual">
        <geometry>
          <mesh>
            <scale>0.7 0.7 0.7</scale>
            <uri>file:///home/aerobase/hexadrone/models/hexadrone_model/meshes/iris_prop_ccw.dae</uri>
          </mesh>
        </geometry>
        <material>
          <ambient>0 0 1</ambient>
          <diffuse>0 0 1</diffuse>
          <specular>0.1 0.1 0.1 1</specular>
        </material>
      </visual>
    </link>
    <joint name="motor4_br_joint" type="revolute">
      <pose relative_to="base_link">0.03 0 -0.03 0 1.570796 0</pose>
      <child>motor4_br_link</child>
      <parent>base_link</parent>
      <axis>
        <xyz>0 0 1</xyz>
        <limit>
          <lower>-1e+16</lower>
          <upper>1e+16</upper>
        </limit>
        <dynamics>
          <damping>0.004</damping>
        </dynamics>
      </axis>
    </joint>

    <!-- motor 2 ccw mid left -->
    <link name="motor2_ml_link">
      <pose relative_to="motor2_ml_joint">0 0 0 0 0 0</pose>
      <inertial>
        <mass>0.025</mass>
        <inertia>
          <ixx>9.75e-06</ixx>
          <ixy>0</ixy>
          <ixz>0</ixz>
          <iyy>0.000166704</iyy>
          <iyz>0</iyz>
          <izz>0.000167604</izz>
        </inertia>
      </inertial>
      <collision name="collision">
        <geometry>
          <cylinder>
            <length>0.005</length>
            <radius>0.07</radius>
          </cylinder>
        </geometry>
      </collision>
      <visual name="visual">
        <geometry>
          <mesh>
            <scale>0.7 0.7 0.7</scale>
            <uri>file:///home/aerobase/hexadrone/models/hexadrone_model/meshes/iris_prop_ccw.dae</uri>
          </mesh>
        </geometry>
        <material>
          <ambient>0 0 1</ambient>
          <diffuse>0 0 1</diffuse>
          <specular>0.1 0.1 0.1 1</specular>
        </material>
      </visual>
    </link>
    <joint name="motor2_ml_joint" type="revolute">
      <pose relative_to="base_link">0.03 0 -0.03 0 1.570796 0</pose>
      <child>motor2_ml_link</child>
      <parent>base_link</parent>
      <axis>
        <xyz>0 0 1</xyz>
        <limit>
          <lower>-1e+16</lower>
          <upper>1e+16</upper>
        </limit>
        <dynamics>
          <damping>0.004</damping>
        </dynamics>
      </axis>
    </joint>

    <!-- motor 1 cw mid right -->
    <link name="motor1_mr_link">
      <pose relative_to="motor1_mr_joint">0 0 0 0 0 0</pose>
      <inertial>
        <mass>0.025</mass>
        <inertia>
          <ixx>9.75e-06</ixx>
          <ixy>0</ixy>
          <ixz>0</ixz>
          <iyy>0.000166704</iyy>
          <iyz>0</iyz>
          <izz>0.000167604</izz>
        </inertia>
      </inertial>
      <collision name="collision">
        <geometry>
          <cylinder>
            <length>0.005</length>
            <radius>0.07</radius>
          </cylinder>
        </geometry>
      </collision>
      <visual name="visual">
        <geometry>
          <mesh>
            <scale>0.7 0.7 0.7</scale>
            <uri>file:///home/aerobase/hexadrone/models/hexadrone_model/meshes/iris_prop_cw.dae</uri>
          </mesh>
        </geometry>
        <material>
          <ambient>0 1 0</ambient>
          <diffuse>0 1 0</diffuse>
          <specular>0.1 0.1 0.1 1</specular>
        </material>
      </visual>
    </link>
    <joint name="motor1_mr_joint" type="revolute">
      <pose relative_to="base_link">0.03 0 -0.03 0 1.570796 0</pose>
      <child>motor1_mr_link</child>
      <parent>base_link</parent>
      <axis>
        <xyz>0 0 1</xyz>
        <limit>
          <lower>-1e+16</lower>
          <upper>1e+16</upper>
        </limit>
        <dynamics>
          <damping>0.004</damping>
        </dynamics>
      </axis>
    </joint>
  </model>
</sdf>
